<?xml version="1.0" ?>

<!-- The name of the robot is given here. -->
<robot name="pizza_cutter">
  <!-- Define a material called "blue" which can be used to colour links. -->
  <material name="blue">
    <color rgba="0 0 0.8 1"/>
  </material>

  <!-- Define a base link which acts as the root link for the robot. -->
  <link name="pizza_cutter_handle">

    <!-- Defines what the link looks like. -->
    <visual>

      <!-- Origin of the visual element. xyz is in metres. rpy stands for roll pitch yaw in radians.
        Note that origin is global. -->
      <origin xyz="0 0 0.1" rpy="0 0 0"/>

      <geometry>
        <box size="0.03 0.03 0.2" />
      </geometry>
    </visual>
  </link>

  <link name="pizza_cutter_blade">
    <visual>
      <origin xyz="0 0 0" rpy="0 0 0"/>
      <geometry>
        <cylinder length="0.01" radius="0.1" />
      </geometry>
      <material name="blue"/>
    </visual>
  </link>

  <joint name="cutting_joint" type="continuous">
    <parent link="pizza_cutter_handle"/>
    <child link="pizza_cutter_blade"/>
    <axis xyz="0 0 1"/>
    <origin xyz="-0.015 0 0.2" rpy="0 ${pi/2.0} 0"/>
  </joint>

</robot>
